Workbook
Name crp: IF(AND(#REF!="© 2011 Spreadsheet123 Ltd. All rights reserved",#REF!="Small Business Templates by Spreadsheet123.com"),1,0)
Name crp: IF(AND(#REF!="© 2011 Spreadsheet123 Ltd. All rights reserved",#REF!="Small Business Templates by Spreadsheet123.com"),1,0)
Name crp: IF(AND(#REF!="© 2011 Spreadsheet123 Ltd. All rights reserved",#REF!="Small Business Templates by Spreadsheet123.com"),1,0)
Name crp: IF(AND(#REF!="© 2011 Spreadsheet123 Ltd. All rights reserved",#REF!="Small Business Templates by Spreadsheet123.com"),1,0)
Name crp: IF(AND(#REF!="© 2011 Spreadsheet123 Ltd. All rights reserved",#REF!="Small Business Templates by Spreadsheet123.com"),1,0)
Name crp: IF(AND(#REF!="© 2011 Spreadsheet123 Ltd. All rights reserved",#REF!="Small Business Templates by Spreadsheet123.com"),1,0)
Name crp: IF(AND(#REF!="© 2011 Spreadsheet123 Ltd. All rights reserved",#REF!="Small Business Templates by Spreadsheet123.com"),1,0)
Name crp: IF(AND(#REF!="© 2011 Spreadsheet123 Ltd. All rights reserved",#REF!="Small Business Templates by Spreadsheet123.com"),1,0)
Name crp: IF(AND(#REF!="© 2011 Spreadsheet123 Ltd. All rights reserved",#REF!="Small Business Templates by Spreadsheet123.com"),1,0)
Name crp: IF(AND(#REF!="© 2011 Spreadsheet123 Ltd. All rights reserved",#REF!="Small Business Templates by Spreadsheet123.com"),1,0)
Name crp: IF(AND(#REF!="© 2011 Spreadsheet123 Ltd. All rights reserved",#REF!="Small Business Templates by Spreadsheet123.com"),1,0)
Name crp: #REF!
Name crp: IF(AND(#REF!="© 2011 Spreadsheet123 Ltd. All rights reserved",#REF!="Small Business Templates by Spreadsheet123.com"),1,0)
Name crp: IF(AND(#REF!="© 2011 Spreadsheet123 Ltd. All rights reserved",#REF!="Small Business Templates by Spreadsheet123.com"),1,0)
Name crp: IF(AND(#REF!="© 2011 Spreadsheet123 Ltd. All rights reserved",#REF!="Small Business Templates by Spreadsheet123.com"),1,0)
Name crp: IF(AND(#REF!="© 2011 Spreadsheet123 Ltd. All rights reserved",#REF!="Small Business Templates by Spreadsheet123.com"),1,0)
Name crp: IF(AND(#REF!="© 2011 Spreadsheet123 Ltd. All rights reserved",#REF!="Small Business Templates by Spreadsheet123.com"),1,0)
Name crp: IF(AND(#REF!="© 2011 Spreadsheet123 Ltd. All rights reserved",#REF!="Small Business Templates by Spreadsheet123.com"),1,0)
Name crp: IF(AND(#REF!="© 2011 Spreadsheet123 Ltd. All rights reserved",#REF!="Small Business Templates by Spreadsheet123.com"),1,0)
Name crp: IF(AND(#REF!="© 2011 Spreadsheet123 Ltd. All rights reserved",#REF!="Small Business Templates by Spreadsheet123.com"),1,0)
Name crp: IF(AND(#REF!="© 2011 Spreadsheet123 Ltd. All rights reserved",#REF!="Small Business Templates by Spreadsheet123.com"),1,0)
Name crp: IF(AND(#REF!="© 2011 Spreadsheet123 Ltd. All rights reserved",#REF!="Small Business Templates by Spreadsheet123.com"),1,0)
Name crp: IF(AND(#REF!="© 2011 Spreadsheet123 Ltd. All rights reserved",#REF!="Small Business Templates by Spreadsheet123.com"),1,0)
Name crp: IF(AND(#REF!="© 2011 Spreadsheet123 Ltd. All rights reserved",#REF!="Small Business Templates by Spreadsheet123.com"),1,0)
Name crp: IF(AND(#REF!="© 2011 Spreadsheet123 Ltd. All rights reserved",#REF!="Small Business Templates by Spreadsheet123.com"),1,0)
Name crp: IF(AND(#REF!="© 2011 Spreadsheet123 Ltd. All rights reserved",#REF!="Small Business Templates by Spreadsheet123.com"),1,0)
Name crp: IF(AND(#REF!="© 2011 Spreadsheet123 Ltd. All rights reserved",#REF!="Small Business Templates by Spreadsheet123.com"),1,0)
Name crp: IF(AND(#REF!="© 2011 Spreadsheet123 Ltd. All rights reserved",#REF!="Small Business Templates by Spreadsheet123.com"),1,0)
Name crp: IF(AND(#REF!="© 2011 Spreadsheet123 Ltd. All rights reserved",#REF!="Small Business Templates by Spreadsheet123.com"),1,0)
Name crp: IF(AND(#REF!="© 2011 Spreadsheet123 Ltd. All rights reserved",#REF!="Small Business Templates by Spreadsheet123.com"),1,0)
Name crp: IF(AND(#REF!="© 2011 Spreadsheet123 Ltd. All rights reserved",#REF!="Small Business Templates by Spreadsheet123.com"),1,0)
Name crp: IF(AND(#REF!="© 2011 Spreadsheet123 Ltd. All rights reserved",#REF!="Small Business Templates by Spreadsheet123.com"),1,0)
Name crp: IF(AND(#REF!="© 2011 Spreadsheet123 Ltd. All rights reserved",#REF!="Small Business Templates by Spreadsheet123.com"),1,0)
Name crp: IF(AND(#REF!="© 2011 Spreadsheet123 Ltd. All rights reserved",#REF!="Small Business Templates by Spreadsheet123.com"),1,0)
Name crp: IF(AND(#REF!="© 2011 Spreadsheet123 Ltd. All rights reserved",#REF!="Small Business Templates by Spreadsheet123.com"),1,0)
Name crp: IF(AND(#REF!="© 2011 Spreadsheet123 Ltd. All rights reserved",#REF!="Small Business Templates by Spreadsheet123.com"),1,0)
Name crp: IF(AND(#REF!="© 2011 Spreadsheet123 Ltd. All rights reserved",#REF!="Small Business Templates by Spreadsheet123.com"),1,0)
Name crp: IF(AND(#REF!="© 2011 Spreadsheet123 Ltd. All rights reserved",#REF!="Small Business Templates by Spreadsheet123.com"),1,0)
Name crp: IF(AND(#REF!="© 2011 Spreadsheet123 Ltd. All rights reserved",#REF!="Small Business Templates by Spreadsheet123.com"),1,0)
Name crp: IF(AND(#REF!="© 2011 Spreadsheet123 Ltd. All rights reserved",#REF!="Small Business Templates by Spreadsheet123.com"),1,0)
Name crp: IF(AND(#REF!="© 2011 Spreadsheet123 Ltd. All rights reserved",#REF!="Small Business Templates by Spreadsheet123.com"),1,0)
Name crp: IF(AND(#REF!="© 2011 Spreadsheet123 Ltd. All rights reserved",#REF!="Small Business Templates by Spreadsheet123.com"),1,0)
Name crp: IF(AND(#REF!="© 2011 Spreadsheet123 Ltd. All rights reserved",#REF!="Small Business Templates by Spreadsheet123.com"),1,0)
Name crp: IF(AND(#REF!="© 2011 Spreadsheet123 Ltd. All rights reserved",#REF!="Small Business Templates by Spreadsheet123.com"),1,0)
Name crp: IF(AND(#REF!="© 2011 Spreadsheet123 Ltd. All rights reserved",#REF!="Small Business Templates by Spreadsheet123.com"),1,0)
Name crp: IF(AND(#REF!="© 2011 Spreadsheet123 Ltd. All rights reserved",#REF!="Small Business Templates by Spreadsheet123.com"),1,0)
Name crp: IF(AND(#REF!="© 2011 Spreadsheet123 Ltd. All rights reserved",#REF!="Small Business Templates by Spreadsheet123.com"),1,0)
Name crp: IF(AND(#REF!="© 2011 Spreadsheet123 Ltd. All rights reserved",#REF!="Small Business Templates by Spreadsheet123.com"),1,0)
Name crp: IF(AND(#REF!="© 2011 Spreadsheet123 Ltd. All rights reserved",#REF!="Small Business Templates by Spreadsheet123.com"),1,0)
Name crp: IF(AND(#REF!="© 2011 Spreadsheet123 Ltd. All rights reserved",#REF!="Small Business Templates by Spreadsheet123.com"),1,0)
Name crp: IF(AND(#REF!="© 2011 Spreadsheet123 Ltd. All rights reserved",#REF!="Small Business Templates by Spreadsheet123.com"),1,0)
Name crp: IF(AND(#REF!="© 2011 Spreadsheet123 Ltd. All rights reserved",#REF!="Small Business Templates by Spreadsheet123.com"),1,0)
Name crp: IF(AND(#REF!="© 2011 Spreadsheet123 Ltd. All rights reserved",#REF!="Small Business Templates by Spreadsheet123.com"),1,0)
Name crp: IF(AND(#REF!="© 2011 Spreadsheet123 Ltd. All rights reserved",#REF!="Small Business Templates by Spreadsheet123.com"),1,0)
Name crp: IF(AND(#REF!="© 2011 Spreadsheet123 Ltd. All rights reserved",#REF!="Small Business Templates by Spreadsheet123.com"),1,0)
Name crp: IF(AND(#REF!="© 2011 Spreadsheet123 Ltd. All rights reserved",#REF!="Small Business Templates by Spreadsheet123.com"),1,0)
Name crp: IF(AND(#REF!="© 2011 Spreadsheet123 Ltd. All rights reserved",#REF!="Small Business Templates by Spreadsheet123.com"),1,0)
Name crp: IF(AND(#REF!="© 2011 Spreadsheet123 Ltd. All rights reserved",#REF!="Small Business Templates by Spreadsheet123.com"),1,0)
Name crp: IF(AND(#REF!="© 2011 Spreadsheet123 Ltd. All rights reserved",#REF!="Small Business Templates by Spreadsheet123.com"),1,0)
Name crp: IF(AND(#REF!="© 2011 Spreadsheet123 Ltd. All rights reserved",#REF!="Small Business Templates by Spreadsheet123.com"),1,0)

Sheet 경쟁사 가격분석
H2: ** KFC 는 바하마 공식 웹사이트 / Popeyes 는 Gofadis 기준
H3: ** 카테고리 평균 가격으로 기입
B4: 구분 | C4: bb.q | D4: KFC | E4: bb.q <> KFC | F4: Popeyes | G4: bb.q <> Popeyes | H4: Note
B5: Whole Chicken | C5: 4.12 | D5: 2.61 | E5: -0.3658 | F5: 단품 없음 (콤보로만 판매) | H5: 타브랜드: 소스 상관없이 가격 동일
B6: Wing | C6: 1.61 | D6: - | F6: - | H6: 타브랜드: 별도 부위 구분 없음
B7: Boneless | C7: 1.62 | D7: - | F7: -
B8: 1-2용 Menu Range (combo, 2/3/5/6p 메뉴) | C8: $9.95~$19.95 | D8: $7.77~$20.00 | F8: $9.15~$56.42 | H8: 각 콤보별 구성 상이 / 파파이스는 일부 콤보 내 음료 포함
B9: French Fries | C9: 4.95 | D9: 4.09 | E9: -0.1737 | F9: 5.65 | G9: 0.1414 | H9: 타브랜드: Large 사이즈 기준
B10: Side Sauce | C10: 1.95 | D10: 0.28 | E10: -0.8564 | F10: 0.65 | G10: -0.6667
B11: Soda | C11: 2.38 | D11: 2.27 | E11: -0.0462 | F11: 3.25 | G11: 0.3655 | H11: 타브랜드: Med 사이즈 기준
B15: bb.q 메뉴 | E15: 판매가_07.26_ver
B16: Sort | D16: Menu | E16: Pcs | F16: Sales Price | G16: Price per pcs | H16: AVG
B17: Chicken | C17: W.C | D17: Golden Original Whole Chicken, Dark | E17: 2 | F17: 11.95 | G17: 5.98 | H17: 4.12
B18: Chicken | C18: W.C | D18: white | E18: 3 | F18: 12.95 | G18: 4.32
B19: Chicken | C19: W.C | D19: (half) | E19: 5 | F19: 17.95 | G19: 3.59
B20: Chicken | C20: W.C | D20: (whole) | E20: 10 | F20: 31.95 | G20: 3.2
B21: Chicken | C21: W.C | D21: Secret Sauce Whole Chicken, Dark | E21: 2 | F21: 11.95 | G21: 5.98
B22: Chicken | C22: W.C | D22: white | E22: 3 | F22: 12.95 | G22: 4.32
B23: Chicken | C23: W.C | D23: (half) | E23: 5 | F23: 17.95 | G23: 3.59
B24: Chicken | C24: W.C | D24: (whole) | E24: 10 | F24: 31.95 | G24: 3.2
B25: Chicken | C25: W.C | D25: Hot Spicy Whole Chicken, Dark | E25: 2 | F25: 11.95 | G25: 5.98
B26: Chicken | C26: W.C | D26: white | E26: 3 | F26: 12.95 | G26: 4.32
B27: Chicken | C27: W.C | D27: (half) | E27: 5 | F27: 17.95 | G27: 3.59
B28: Chicken | C28: W.C | D28: (whole) | E28: 10 | F28: 31.95 | G28: 3.2
B29: Half & Half | C29: W.C | D29: Half & Half Whole Chicken (Secret) | E29: 10 | F29: 31.95 | G29: 3.2
B30: Half & Half | C30: W.C | D30: Half & Half Whole Chicken (Hot spicy) | E30: 10 | F30: 31.95 | G30: 3.2
B31: Chicken | C31: Wings | D31: Golden Original Wings | E31: 6 | F31: 10.95 | G31: 1.83 | H31: 1.7
B32: Chicken | C32: Wings | E32: 12 | F32: 19.95 | G32: 1.66
B33: Chicken | C33: Wings | E33: 18 | F33: 28.95 | G33: 1.61
B34: Chicken | C34: Wings | D34: Secret Sauce Wings | E34: 6 | F34: 10.95 | G34: 1.83
B35: Chicken | C35: Wings | E35: 12 | F35: 19.95 | G35: 1.66
B36: Chicken | C36: Wings | E36: 18 | F36: 28.95 | G36: 1.61
B37: Chicken | C37: Wings | D37: Hot Spicy Wings | E37: 6 | F37: 10.95 | G37: 1.83
B38: Chicken | C38: Wings | E38: 12 | F38: 19.95 | G38: 1.66
B39: Chicken | C39: Wings | E39: 18 | F39: 28.95 | G39: 1.61
B40: Chicken | C40: Wings | D40: Honey Garlic Wings | E40: 6 | F40: 10.95 | G40: 1.83
B41: Chicken | C41: Wings | E41: 12 | F41: 19.95 | G41: 1.66
B42: Chicken | C42: Wings | E42: 18 | F42: 28.95 | G42: 1.61
B43: Chicken | C43: Wings | D43: Soy Garlic Wings | E43: 6 | F43: 10.95 | G43: 1.83
B44: Chicken | C44: Wings | E44: 12 | F44: 19.95 | G44: 1.66
...

Sheet Competitor Price Analysis
B4: Menu Item | C4: Description | D4: Price (JMD) | E4: Price (USD)
A5: * 1 USD = 156JMD
A6: BirdShack
A7: Family Meals | B7: FLEX 9 | C7: 9pcs Chicken + 12 fries +2colslaw + 1.2L Soda | D7: 5125 | E7: =D7/156 -> 32.852564
B8: FLEX 12 | C8: 12pcs Chicken + 12 fries +3colslaw + Cornbread Rolls + 1.2L Soda | D8: 6745 | E8: =D8/156 -> 43.237179
B9: FLEX 15 | C9: 15 pcs Chicken + 1.2L Soda | D9: 6535 | E9: =D9/156 -> 41.891026
B10: FLEX 21 | C10: 21 pcs Chicken + 1.2L Soda | D10: 8735 | E10: =D10/156 -> 55.99359
B11: FLEX BOX COMBO | C11: 1pcs Chicken or 3 wings + 1Chicken sandwich + 3 Wedge . Fries + 16oz Soda | D11: 1800 | E11: =D11/156 -> 11.538462
B12: STARTA BOX | C12: 1pcs Chicken + 3 Potato Wedge or reg fries + 1 Cornbrean Roll + 16 oz Soda | D12: 690 | E12: =D12/156 -> 4.4230769
A13: Combo | B13: Jumbo Wings Combo (6pc) | C13: 6pcs Wing + 3 wedge fries or reg fries + 16oz Soda | D13: 1320 | E13: =D13/156 -> 8.4615385
B14: Jumbo Wings Combo (10pc) | C14: 10pcs Wing + 3 wedge fries or reg fries + 16oz Soda | D14: 1950 | E14: =D14/156 -> 12.5
B15: Jumbo Wings Combo (16pc) | C15: 16pcs Wing + 3 wedge fries or reg fries + 16oz Soda | D15: 2750 | E15: =D15/156 -> 17.628205
B16: Double Up | C16: 2pc of Chicken + 3 Fries + 16oz Soda | D16: 1045 | E16: =D16/156 -> 6.6987179
B17: Hatrik | C17: 3pc of Chicken + 3 Fries + 16oz Soda | D17: 1415 | E17: =D17/156 -> 9.0705128
B18: Chicken Sandwich Combo | C18: Chicken Sandwich + 3 fries + 16oz Soda | D18: 1200 | E18: =D18/156 -> 7.6923077
B19: Hi-5 | C19: 5pc of Chicken + 3 Fries + 16oz Soda | D19: 2445 | E19: =D19/156 -> 15.673077
B20: 6LUV | C20: 6pc of Chicken + 6 Fries + Coleslaw + 2 16oz Soda | D20: 2935 | E20: =D20/156 -> 18.814103
A21: Side | B21: Wedges | D21: 250 | E21: =D21/156 -> 1.6025641
B22: Regular Fries | D22: 250 | E22: =D22/156 -> 1.6025641
B23: Coleslaw | D23: 300 | E23: =D23/156 -> 1.9230769
B24: Cornbread Roll | D24: 150 | E24: =D24/156 -> 0.96153846
B25: Ranch | D25: 120 | E25: =D25/156 -> 0.76923077
B26: Honey Mustard | D26: 120 | E26: =D26/156 -> 0.76923077
A27: Beverages | B27: Tru-Juice | D27: 300 | E27: =D27/156 -> 1.9230769
B28: CranWata | D28: 225 | E28: =D28/156 -> 1.4423077
B29: Wata | D29: 150 | E29: =D29/156 -> 0.96153846
B30: Soda | D30: 225 | E30: =D30/156 -> 1.4423077
A31: KFC
B33: Meal Deal | C33: 2pcs chicken + 1Fries + 1Soda | D33: 1050 | E33: =D33/156 -> 6.7307692
B34: Big Deal | C34: 3pcs Chicken + 1fries + 1 Soda | D34: 1420 | E34: =D34/156 -> 9.1025641
B35: Big Six | C35: 6pcs Chicken + 2 fries + 2 Soda + 1Coleslaw | D35: 2940 | E35: =D35/156 -> 18.846154
B36: Chicken Box | C36: 1pcs Chicken + 1 bread + fries | D36: 600 | E36: =D36/156 -> 3.8461538
B37: Chicken Box Combo | C37: 1 Chicken + 1 bread + 1fries + 1 Soda | D37: 680 | E37: =D37/156 -> 4.3589744
A38: Popeyes
B40: Popeyes 2pc Combo | C40: 2pcs Chicken + 1 bread + 1 side | D40: 1060 | E40: =D40/156 -> 6.7948718
B41: Popeyes 3pc Combo | C41: 3pcs Chicken + 1 bread + 1 side(fries) | D41: 1410 | E41: =D41/156 -> 9.0384615
B42: Popeyes 5pc Combo | C42: 5pcs Chicken + 1 bread + 1 side(fries) | D42: 2370 | E42: =D42/156 -> 15.192308
B43: Popeyes 21pc Combo | C43: 5pcs Chicken + 2 bread + 2 side(fries) | D43: 7850 | E43: =D43/156 -> 50.320513
B44: Popeyes 5pc Tenders Combo | C44: 5pc Tender + 1bread + 2 Sauce | D44: 1490 | E44: =D44/156 -> 9.5512821
B45: Popeyes 3pc Tenders Combo | C45: 3pc Tender + 1bread + 1 side | D45: 990 | E45: =D45/156 -> 6.3461538

Sheet Honduras(Total Final)
A2: bb.q Chicken Honduras Menu Food Cost | O2: Raw chicken (price per kg)
A3: Menu | P3: FL | Q3: Bahama 업데이트 전 | R3: Honduras (10/6)
O4: Whole (1.3~1.4kg) / 2.87~3.08LB | P4: 1.9 | Q4: 3.85 | R4: 3.05
A5: Sort | C5: Menu | E5: Description | F5: Sales Price HNL | G5: Sales Price USD | H5: Food Cost Dine In | I5: Food Cost Take Out | J5: Cost% Dine-In | K5: Cost% Take Out | L5: AVG D/I 50% + T/G 50% | M5: AVG Total | O5: Wing | P5: 3.44 | Q5: 1.7 | R5: 5.39
A6: Chicken (Bone In) | B6: Fried | C6: Golden Fried Chicken | E6: 5pcs (0.5 Bird) | F6: 300 | G6: =F6/24.65 -> 12.170385 | H6: ='BI_Golden Fried(5pc)'!$D$6 -> 4.5800398 | I6: ='BI_Golden Fried(5pc)'!$D$7 -> 5.3742867 | J6: =H6/G6 -> 0.3763266 | K6: =I6/G6 -> 0.44158722 | L6: =AVERAGE(J6:K35) -> 0.37903523 | M6: =AVERAGE(L6,L36,L68,L98,L100,L109,L130,L135) -> 0.27868524 | O6: BNL (Thigh) | P6: 2.23 | Q6: 4.03 | R6: 4.47
E7: 10pcs (1 Bird) | F7: 600 | G7: =F7/24.65 -> 24.340771 | H7: ='BI_Golden Fried(10pc)'!$D$6 -> 9.1600795 | I7: ='BI_Golden Fried(10pc)'!$D$7 -> 10.043421 | J7: =H7/G7 -> 0.3763266 | K7: =I7/G7 -> 0.41261721
C8: Classic Fried Chicken | E8: 5pcs (0.5 Bird) | F8: 300 | G8: =F8/24.65 -> 12.170385 | H8: ='BI_Classic(5pc)'!$D$6 -> 4.0285688 | I8: ='BI_Classic(5pc)'!$D$7 -> 4.7018843 | J8: =H8/G8 -> 0.33101407 | K8: =I8/G8 -> 0.38633816 | O8: BNL (Breast) | P8: - | Q8: - | R8: 6.06
E9: 10pcs (1 Bird) | F9: 600 | G9: =F9/24.65 -> 24.340771 | H9: ='BI_Classic(10pc)'!$D$6 -> 8.0571375 | I9: ='BI_Classic(10pc)'!$D$7 -> 8.9404789 | J9: =H9/G9 -> 0.33101407 | K9: =I9/G9 -> 0.36730467
B10: Sauced | C10: Secret Sacued Chicken | E10: 5pcs (0.5 Bird) | F10: 350 | G10: =F10/24.65 -> 14.198783 | H10: ='BI_Secret (5pc)'!$D$6 -> 5.6382286 | I10: ='BI_Secret (5pc)'!$D$7 -> 6.4471234 | J10: =H10/G10 -> 0.39709239 | K10: =I10/G10 -> 0.45406169
E11: 10pcs (1 Bird) | F11: 700 | G11: =F11/24.65 -> 28.397566 | H11: ='BI_Secret (10pc)'!$D$6 -> 11.276457 | I11: ='BI_Secret (10pc)'!$D$7 -> 12.174446 | J11: =H11/G11 -> 0.39709239 | K11: =I11/G11 -> 0.42871443
C12: Hot Spicy Chicken | E12: 5pcs (0.5 Bird) | F12: 350 | G12: =F12/24.65 -> 14.198783 | H12: ='BI_Hot Spicy(5pc)'!$D$6 -> 5.3358316 | I12: ='BI_Hot Spicy(5pc)'!$D$7 -> 6.1447264 | J12: =H12/G12 -> 0.375795 | K12: =I12/G12 -> 0.4327643
E13: 10pcs (1 Bird) | F13: 700 | G13: =F13/24.65 -> 28.397566 | H13: ='BI_Hot Spicy (10pc)'!$D$6 -> 10.671663 | I13: ='BI_Hot Spicy (10pc)'!$D$7 -> 11.569652 | J13: =H13/G13 -> 0.375795 | K13: =I13/G13 -> 0.40741705
C14: Honey Garlic Chicken | E14: 5pcs (0.5 Bird) | F14: 350 | G14: =F14/24.65 -> 14.198783 | H14: ='BI_Honey Garlic(5pc)'!$D$6 -> 4.5619906 | I14: ='BI_Honey Garlic(5pc)'!$D$7 -> 5.3708854 | J14: =H14/G14 -> 0.32129448 | K14: =I14/G14 -> 0.37826378
E15: 10pcs (1 Bird) | F15: 700 | G15: =F15/24.65 -> 28.397566 | H15: ='BI_Honey Garlic(10pc)'!$D$6 -> 9.1239812 | I15: ='BI_Honey Garlic(10pc)'!$D$7 -> 10.02197 | J15: =H15/G15 -> 0.32129448 | K15: =I15/G15 -> 0.35291653
C16: Soy Garlic Chicken | E16: 5pcs (0.5 Bird) | F16: 350 | G16: =F16/24.65 -> 14.198783 | H16: ='BI_Soy Garlic(5pc)'!$D$6 -> 4.358961 | I16: ='BI_Soy Garlic(5pc)'!$D$7 -> 5.1678558 | J16: =H16/G16 -> 0.30699539 | K16: =I16/G16 -> 0.3639647
E17: 10pcs (1 Bird) | F17: 700 | G17: =F17/24.65 -> 28.397566 | H17: ='BI_Soy Garlic(10pc)'!$D$6 -> 8.717922 | I17: ='BI_Soy Garlic(10pc)'!$D$7 -> 9.4679001 | J17: =H17/G17 -> 0.30699539 | K17: =I17/G17 -> 0.33340534
C18: Galbi Chicken | E18: 5pcs (0.5 Bird) | F18: 350 | G18: =F18/24.65 -> 14.198783 | H18: ='BI_Galbi(5pc)'!$D$6 -> 4.9738892 | I18: ='BI_Galbi(5pc)'!$D$7 -> 5.7827839 | J18: =H18/G18 -> 0.35030391 | K18: =I18/G18 -> 0.40727321
E19: 10pcs (1 Bird) | F19: 700 | G19: =F19/24.65 -> 28.397566 | H19: ='BI_Galbi (10pc)'!$D$6 -> 9.9368995 | I19: ='BI_Galbi (10pc)'!$D$7 -> 10.834889 | J19: =H19/G19 -> 0.34992082 | K19: =I19/G19 -> 0.38154287
C20: Hot Galbi Chikcen | E20: 5pcs (0.5 Bird) | F20: 350 | G20: =F20/24.65 -> 14.198783 | H20: ='BI_Hot Galbi (5pc)'!$D$6 -> 4.9738892 | I20: ='BI_Hot Galbi (5pc)'!$D$7 -> 5.7827839 | J20: =H20/G20 -> 0.35030391 | K20: =I20/G20 -> 0.40727321
E21: 10pcs (1 Bird) | F21: 700 | G21: =F21/24.65 -> 28.397566 | H21: ='BI_Hot Galbi (10pc)'!$D$6 -> 12.22752 | I21: ='BI_Hot Galbi (10pc)'!$D$7 -> 13.125509 | J21: =H21/G21 -> 0.43058337 | K21: =I21/G21 -> 0.46220542
C22: Gang-Jeong Chicken | E22: 5pcs (0.5 Bird) | F22: 350 | G22: =F22/24.65 -> 14.198783 | H22: ='BI_Gangjeong (5pc)'!$D$6 -> 5.0113418 | I22: ='BI_Gangjeong (5pc)'!$D$7 -> 5.8202366 | J22: =H22/G22 -> 0.35294165 | K22: =I22/G22 -> 0.40991095
E23: 10pcs (1 Bird) | F23: 700 | G23: =F23/24.65 -> 28.397566 | H23: ='BI_Gangjeong(10pc)'!$D$6 -> 10.022684 | I23: ='BI_Gangjeong(10pc)'!$D$7 -> 10.772662 | J23: =H23/G23 -> 0.35294165 | K23: =I23/G23 -> 0.37935159
C24: Gangnam Style Chicken | E24: 5pcs (0.5 Bird) | F24: 350 | G24: =F24/24.65 -> 14.198783 | H24: ='BI_Gangnam Style(5pc)'!$D$6 -> 4.596638 | I24: ='BI_Gangnam Style(5pc)'!$D$7 -> 5.4055327 | J24: =H24/G24 -> 0.32373465 | K24: =I24/G24 -> 0.38070395
E25: 10pcs (1 Bird) | F25: 700 | G25: =F25/24.65 -> 28.397566 | H25: ='BI_Gangnam Style(10pc)'!$D$6 -> 9.1932759 | I25: ='BI_Gangnam Style(10pc)'!$D$7 -> 10.091265 | J25: =H25/G25 -> 0.32373465 | K25: =I25/G25 -> 0.35535669
C26: Phase 2_Caribbean Spicy Chicken | E26: 5pcs (0.5 Bird) | F26: 350 | G26: =F26/24.65 -> 14.198783 | H26: ='BI_Caribbean (5pc)'!$D$6 -> 4.9684961 | I26: ='BI_Caribbean (5pc)'!$D$7 -> 5.7773909 | J26: =H26/G26 -> 0.34992408 | K26: =I26/G26 -> 0.40689339
E27: 10pcs (1 Bird) | F27: 700 | G27: =F27/24.65 -> 28.397566 | H27: ='BI_Caribbean(10pc)'!$D$6 -> 9.9369922 | I27: ='BI_Caribbean(10pc)'!$D$7 -> 10.834981 | J27: =H27/G27 -> 0.34992408 | K27: =I27/G27 -> 0.38154613
C28: Phase 2_Mala Hot Chicekn | E28: 5pcs (0.5 Bird) | F28: 350 | G28: =F28/24.65 -> 14.198783 | H28: ='BI_Mala Hot(5pc)'!$D$6 -> 5.5481712 | I28: ='BI_Mala Hot(5pc)'!$D$7 -> 6.357066 | J28: =H28/G28 -> 0.39074977 | K28: =I28/G28 -> 0.44771907
E29: 10pcs (1 Bird) | F29: 700 | G29: =F29/24.65 -> 28.397566 | H29: ='BI_Mala Hot(10pc)'!$D$6 -> 11.096342 | I29: ='BI_Mala Hot(10pc)'!$D$7 -> 11.994332 | J29: =H29/G29 -> 0.39074977 | K29: =I29/G29 -> 0.42237182
B30: Flakes | C30: Phase 2_Creamy Onion Chicekn | E30: 5pcs (0.5 Bird) | F30: 350 | G30: =F30/24.65 -> 14.198783 | H30: ='BI_Creamy Onion(5pc)'!$D$6 -> 5.8189164 | I30: ='BI_Creamy Onion(5pc)'!$D$7 -> 6.6278111 | J30: =H30/G30 -> 0.40981797 | K30: =I30/G30 -> 0.46678727
E31: 10pcs (1 Bird) | F31: 700 | G31: =F31/24.65 -> 28.397566 | H31: ='BI_Creamy Onion(10pc)'!$D$6 -> 11.637833 | I31: ='BI_Creamy Onion(10pc)'!$D$7 -> 12.535822 | J31: =H31/G31 -> 0.40981797 | K31: =I31/G31 -> 0.44144001
C32: Phase 2_Creamy Jalapeno Chicken | E32: 5pcs (0.5 Bird) | F32: 350 | G32: =F32/24.65 -> 14.198783 | H32: ='BI_Creamy Jalapeno(5pc)'!$D$6 -> 4.9823892 | I32: ='BI_Creamy Jalapeno(5pc)'!$D$7 -> 5.791284 | J32: =H32/G32 -> 0.35090255 | K32: =I32/G32 -> 0.40787186
E33: 10pcs (1 Bird) | F33: 700 | G33: =F33/24.65 -> 28.397566 | H33: ='BI_Creamy Jalapeno(10pc)'!$D$6 -> 9.9647784 | I33: ='BI_Creamy Jalapeno(10pc)'!$D$7 -> 10.862768 | J33: =H33/G33 -> 0.35090255 | K33: =I33/G33 -> 0.3825246
C34: Cheesling Chicken | E34: 5pcs (0.5 Bird) | F34: 350 | G34: =F34/24.65 -> 14.198783 | H34: ='BI_Cheesling(5pc)'!$D$6 -> 4.6114321 | I34: ='BI_Cheesling(5pc)'!$D$7 -> 5.4203269 | J34: =H34/G34 -> 0.32477657 | K34: =I34/G34 -> 0.38174588
E35: 10pcs (1 Bird) | F35: 700 | G35: =F35/24.65 -> 28.397566 | H35: ='BI_Cheesling(10pc)'!$D$6 -> 9.2228642 | I35: ='BI_Cheesling(10pc)'!$D$7 -> 10.120853 | J35: =H35/G35 -> 0.32477657 | K35: =I35/G35 -> 0.35639862
A36: Chicken (Boneless) | B36: Fried | C36: Golden Fried Chicken | E36: 10 pcs | F36: 300 | G36: =F36/24.65 -> 12.170385 | H36: ='BL_Golden Fried(10pc)'!$D$6 -> 3.7491816 | I36: ='BL_Golden Fried(10pc)'!$D$7 -> 4.4224971 | J36: =H36/G36 -> 0.30805775 | K36: =I36/G36 -> 0.36338185 | L36: =AVERAGE(J36:K67) -> 0.31120416
E37: 20 pcs | F37: 600 | G37: =F37/24.65 -> 24.340771 | H37: ='BL_Golden Fried(20pc)'!$D$6 -> 7.4983632 | I37: ='BL_Golden Fried(20pc)'!$D$7 -> 8.3203118 | J37: =H37/G37 -> 0.30805775 | K37: =I37/G37 -> 0.34182615
C38: Classic Fried Chicken | E38: 10 pcs | F38: 300 | G38: =F38/24.65 -> 12.170385 | H38: ='BL_Classic(10pc)'!$D$6 -> 3.4098148 | I38: ='BL_Classic(10pc)'!$D$7 -> 4.0831304 | J38: =H38/G38 -> 0.28017312 | K38: =I38/G38 -> 0.33549721
E39: 20 pcs | F39: 600 | G39: =F39/24.65 -> 24.340771 | H39: ='BL_Classic(20pc)'!$D$6 -> 6.8196296 | I39: ='BL_Classic(20pc)'!$D$7 -> 7.6415783 | J39: =H39/G39 -> 0.28017312 | K39: =I39/G39 -> 0.31394151
C40: Golden Fried Tender | E40: 10 pcs | F40: 300 | G40: =F40/24.65 -> 12.170385 | H40: ='Golden Fried Tender(10pc)'!$D$6 -> 4.5022685 | I40: ='Golden Fried Tender(10pc)'!$D$7 -> 5.1755841 | J40: =H40/G40 -> 0.3699364 | K40: =I40/G40 -> 0.42526049
E41: 20 pcs | F41: 600 | G41: =F41/24.65 -> 24.340771 | H41: ='Golden Fried Tender(20pc)'!$D$6 -> 9.004537 | I41: ='Golden Fried Tender(20pc)'!$D$7 -> 9.8411336 | J41: =H41/G41 -> 0.3699364 | K41: =I41/G41 -> 0.40430657
...

Sheet Chicken Sales Unit Configur
B1: Chicken Sales Unit Configuration (Honduras)
B2: no. | D2: Fried Chicken - Whole Chicken | E2: Price / HNL | H2: Food Cost
E3: Half Size (8pcs) | F3: Whole Size(16pcs) | I3: Total
B4: 1 | C4: Phase 1 | D4: Golden Fried Chicken | E4: ='Honduras(Total Final)'!F6 -> 300 | F4: ='Honduras(Total Final)'!F7 -> 600 | H4: ='Honduras(Total Final)'!L6 -> 0.37903523 | I4: =AVERAGE(H4,H20,H37,H53,H55,H59,H71,H76) -> 0.27868524
D5: Classic Fried Chicken
D6: Secret Sacued Chicken | E6: ='Honduras(Total Final)'!F10 -> 350 | F6: ='Honduras(Total Final)'!F11 -> 700
D7: Hot Spicy Chicken
D8: Honey Garlic Chicken
D9: Soy Garlic Chicken
D10: Galbi Chicken
D11: Hot Galbi Chikcen
D12: Gang-Jeong Chicken
D13: Gangnam Style Chicken
D14: Cheesling Chicken
C15: Phase 2 | D15: Caribbean Spicy Chicken
D16: Mala Hot Chicekn
D17: Creamy Onion Chicekn | E17: ='Honduras(Total Final)'!F30 -> 350 | F17: ='Honduras(Total Final)'!G31 -> 28.397566
D18: Creamy Jalapeno Chicken
D19: Fried Chicken - Boneless | E19: 10pcs | F19: 20pcs
B20: 1 | C20: Phase 1 | D20: Golden Fried Chicken | E20: ='Honduras(Total Final)'!F36 -> 300 | F20: ='Honduras(Total Final)'!F37 -> 600 | H20: ='Honduras(Total Final)'!L36 -> 0.31120416
D21: Classic Fried Chicken
D22: Golden Fried Tender
D23: Secret Sacued Chicken | E23: ='Honduras(Total Final)'!F42 -> 350 | F23: ='Honduras(Total Final)'!F43 -> 700
D24: Hot Spicy Chicken
D25: Honey Garlic Chicken
D26: Soy Garlic Chicken
D27: Galbi Chicken
D28: Hot Galbi Chikcen
D29: Gang-Jeong Chicken
D30: Gangnam Style Chicken
D31: Cheesling Chicken
C32: Phase 2 | D32: Caribbean Spicy Chicken
D33: Mala Hot Chicekn
D34: Creamy Onion Chicekn
D35: Creamy Jalapeno Chicken
D36: Fried Chicken - wing | E36: 10pcs | F36: 20pcs
B37: 1 | C37: Phase 1 | D37: Golden Fried Chicken | E37: ='Honduras(Total Final)'!F68 -> 300 | F37: ='Honduras(Total Final)'!F69 -> 600 | H37: ='Honduras(Total Final)'!L68 -> 0.27801889
D38: Classic Fried Chicken
D39: Secret Sacued Chicken | E39: ='Honduras(Total Final)'!F72 -> 350 | F39: ='Honduras(Total Final)'!F73 -> 700
D40: Hot Spicy Chicken
...

Sheet Master
A1: bb.q chicken food cost
Q2: 보고용
J3: #VALUE! | K3: {=_FV(J3,"Apertura")} -> 26.3449 | L3: =420/8 -> 52.5
A4: 카테고리 (Category) | B4: 품목명 (Item Name) | C4: 품목명 (Item Name) | D4: Manufacturer or Supplier | E4: Standard package (표준규격) | F4: Unit (무게) | H4: Quantity (g) | J4: Price ($) | K4: Price/g | L4: Input (g or %) | P4: Usage% (수율) | Q4: Note | S4: =16*S21 -> 453.592
I5: Lempiras
A6: 원료육 | B6: 홀치킨 | C6: Whole Chicken | D6: Cardeca | E6: 1 | F6: 1000 | G6: g | H6: 1000 | I6: 74.96 | J6: =+I6/$K$3 -> 2.8453325 | K6: =J6/H6 -> 0.0028453325 | L6: 650 | N6: 1300 | P6: 98 | Q6: Half (M): 650g / Whole (L): 1300g | R6: lb | S6: g
B7: 파티윙 | C7: Party Wings | E7: 1 | F7: 1000 | G7: g | H7: 1000 | I7: 60.5 | J7: =+I7/$K$3 -> 2.2964597 | K7: =J7/H7 -> 0.0022964597 | L7: 300 | M7: =L7*2 -> 600 | O7: =L7*3 -> 900 | P7: 95 | Q7: 윙- S: 8PC(420g) / M: 16PC (840g) / L: 24PC (1260g)] 본레스-S: 8PC(320g) / M: 16PC (640g) / L: 24PC (960g) | R7: 1 | S7: 453.592
B8: 순살 엉치살 | C8: Boneless Thigh | E8: 1 | F8: 1000 | G8: g | H8: 1000 | I8: 110.23 | J8: =+I8/$K$3 -> 4.1841115 | K8: =J8/H8 -> 0.0041841115 | L8: 240 | M8: =L8*2 -> 480 | O8: =L8*3 -> 720 | P8: 80 | R8: kg | S8: g
B9: 순살 가슴살 | C9: Boneless Breast | E9: 1 | F9: 1000 | G9: g | H9: 1000 | I9: 149.91 | J9: =+I9/$K$3 -> 5.6902854 | K9: =J9/H9 -> 0.0056902854 | P9: 80 | R9: 1 | S9: 1000
B11: 홀치킨_시스코 7월 가격 | C11: Whole Chicken | E11: 72/6.5oz | F11: 29.25 | G11: # | H11: =F11*S7 -> 13267.566 | J11: 93.26 | K11: =J11/H11 -> 0.0070291717 | L11: 650 | N11: 1300 | P11: 90 | Q11: Half (M): 650g / Whole L): 1300g | R11: G | S11: g | T11: Cooking Oil
B12: 파티윙_시스코 7월 가격 | C12: Party Wings IQF | E12: 6/5# | F12: 30 | G12: # | H12: =F12*S7 -> 13607.76 | J12: 126.06 | K12: =J12/H12 -> 0.0092638318 | L12: 420 | M12: =L12*2 -> 840 | O12: =L12*3 -> 1260 | P12: 95 | Q12: 윙- S: 8PC(420g) / M: 16PC (840g) / L: 24PC (1260g)] 본레스-S: 8PC(320g) / M: 16PC (640g) / L: 24PC (960g) | R12: 1 | S12: 3785.42
B13: 순살 엉치살_시스코 7월 가격 | C13: Boneless Thigh | E13: 1/40# | F13: 40 | G13: # | H13: =F13*S7 -> 18143.68 | J13: 100.79 | K13: =J13/H13 -> 0.0055551024 | L13: 320 | M13: =L13*2 -> 640 | O13: =L13*3 -> 960 | P13: 80
B14: 순살 가슴살_시스코 7월 가격 | C14: Boneless Breast | E14: 2/5# | F14: 10 | G14: # | H14: =F14*S7 -> 4535.92 | J14: 91.1 | K14: =J14/H14 -> 0.020084128 | P14: 80 | R14: fl.oz | S14: g | T14: Cooking Oil
R15: 1 | S15: 26.02
B16: 파티윙 | C16: Party Wings | E16: 1/40# | F16: 40 | G16: # | H16: =F16*S7 -> 18143.68 | J16: 135.99 | K16: =J16/H16 -> 0.0074951719 | L16: 420 | M16: =L16*2 -> 840 | O16: =L16*3 -> 1260 | P16: 95 | Q16: 윙- S: 8PC(420g) / M: 16PC (840g) / L: 24PC (1260g)] 본레스-S: 8PC(320g) / M: 16PC (640g) / L: 24PC (960g)
B17: 순살 엉치살 | C17: Boneless Thigh | E17: 1/40# | F17: 40 | G17: # | H17: =F17*S7 -> 18143.68 | J17: 89.76 | K17: =J17/H17 -> 0.0049471772 | L17: 320 | M17: =L17*2 -> 640 | O17: =L17*3 -> 960 | P17: 80 | R17: Liter | S17: g
B18: 순살 가슴살 | C18: Boneless Breast | E18: 1/40# | F18: 40 | G18: # | H18: =F18*S7 -> 18143.68 | J18: 86.02 | K18: =J18/H18 -> 0.0047410448 | P18: 80 | R18: 1 | S18: 1000
B20: 홀치킨 | C20: Whole Chicken | E20: 1/50# | F20: 50 | G20: # | H20: =F20*S7 -> 22679.6 | J20: 77.5 | K20: =J20/H20 -> 0.0034171679 | L20: 650 | N20: 1300 | P20: 90 | Q20: Half (M): 650g / Whole L): 1300g | R20: oz | S20: g
B21: 파티윙 | C21: Party Wings | E21: 1/40# | F21: 40 | G21: # | H21: =F21*S7 -> 18143.68 | J21: 148.6 | K21: =J21/H21 -> 0.0081901797 | L21: 420 | M21: =L21*2 -> 840 | O21: =L21*3 -> 1260 | P21: 95 | Q21: 윙- S: 8PC(420g) / M: 16PC (840g) / L: 24PC (1260g)] 본레스-S: 8PC(320g) / M: 16PC (640g) / L: 24PC (960g) | R21: 1 | S21: 28.3495
B22: 순살 엉치살 | C22: Boneless Thigh | E22: 1/40# | F22: 40 | G22: # | H22: =F22*S7 -> 18143.68 | J22: 86.95 | K22: =J22/H22 -> 0.0047923023 | L22: 320 | M22: =L22*2 -> 640 | O22: =L22*3 -> 960 | P22: 80
B23: 순살 가슴살 | C23: Boneless Breast | E23: 1/40# | F23: 40 | G23: # | H23: =F23*S7 -> 18143.68 | J23: 62 | K23: =J23/H23 -> 0.0034171679 | P23: 80 | R23: *원가계산시 원료육 Maximum것 사용함.
B25: 홀치킨 | C25: Whole Chicken | E25: 1/50# | F25: 50 | G25: # | H25: =F25*S7 -> 22679.6 | J25: 69.2 | K25: =J25/H25 -> 0.0030512002 | L25: 650 | N25: 1300 | P25: 90 | Q25: Half (M): 650g / Whole L): 1300g
B26: 파티윙 | C26: Party Wings | E26: 1/40# | F26: 40 | G26: # | H26: =F26*S7 -> 18143.68 | J26: 148.28 | K26: =J26/H26 -> 0.0081725427 | L26: 420 | M26: =L26*2 -> 840 | O26: =L26*3 -> 1260 | P26: 95 | Q26: 윙- S: 8PC(420g) / M: 16PC (840g) / L: 24PC (1260g)] 본레스-S: 8PC(320g) / M: 16PC (640g) / L: 24PC (960g)
B27: 순살 엉치살 | C27: Boneless Thigh | E27: 1/40# | F27: 40 | G27: # | H27: =F27*S7 -> 18143.68 | J27: 90.82 | K27: =J27/H27 -> 0.0050055997 | L27: 320 | M27: =L27*2 -> 640 | O27: =L27*3 -> 960 | P27: 80
A29: 오일 | B29: 카놀라유 | C29: Canola Oil | D29: MAYAB | E29: 1G | F29: 1 | G29: G | H29: =F29*S12 -> 3785.42 | I29: 311 | J29: =+I29/$K$3 -> 11.804941 | K29: =J29/H29 -> 0.0031185288 | L29: 0.25 | P29: 100 | Q29: 원료육 중량대비 25%
B30: 팜유 | C30: Palm Oil | D30: Hondu Palma | E30: 5L | F30: 5 | G30: L | H30: =F30*S18 -> 5000 | J30: =+I30/$K$3 -> 0 | K30: =J30/H30 -> 0 | P30: 100 | Q30: 원료육 중량대비 25%
B31: 해바라기 유 | C31: Sunflower Oil | D31: Hondu Palma | E31: 1.32 L | F31: 1.32 | G31: L | H31: =F31*S18 -> 1320 | I31: 394.95 | J31: =+I31/$K$3 -> 14.991516 | K31: =J31/H31 -> 0.011357209 | L31: 3.5 | M31: 7 | N31: 10 | P31: 100 | Q31: 원료육 중량대비 25%
B32: 올리브오일 | C32: Oilve Oil | D32: Comit | E32: 1L | F32: 1 | G32: L | H32: =F32*S18 -> 1000 | I32: 393.59 | J32: =+I32/$K$3 -> 14.939893 | K32: =J32/H32 -> 0.014939893 | P32: 100 | Q32: 원료육 중량대비 25%
B33: 고추기름 | C33: Chili Oil | E33: 80g | F33: 80 | G33: g | H33: 80 | J33: 5.99 | K33: =J33/H33 -> 0.074875 | P33: 100
B34: 혼합유 | C34: Mix Oil | D34: Hondu Palma | E34: 35LB | F34: 35 | G34: # | H34: =F34*S7 -> 15875.72 | I34: 740 | J34: =+I34/$K$3 -> 28.088928 | K34: =J34/H34 -> 0.001769301 | Q34: 원료육 중량대비 25%
A35: 파우더 | B35: 치즐링 파우더 | C35: Cheese Flavor Seasoning | D35: HQ | E35: 500g/15bag | F35: =500*15 -> 7500 | G35: g | H35: 7500 | I35: 2480.5 | J35: =+I35/$K$3 -> 94.154846 | K35: =J35/H35 -> 0.012553979 | L35: 0.07 | P35: 98
B36: #2 마리네이드 파우더 | C36: Marinade Powder Mix | D36: HQ | E36: 5kg/4bag | F36: 20 | G36: kg | H36: =F36*$S$9 -> 20000 | I36: 4163.25 | J36: =+I36/$K$3 -> 158.02869 | K36: =J36/H36 -> 0.0079014344 | L36: 0.013 | N36: 0.012 | P36: 98 | Q36: 홀 & 윙: 1.3% / 본레스: 1.2%
B37: 비비윙 염지제 | C37: Marinade No 5 | E37: 5kg/1bag | F37: 5 | G37: kg | H37: =F37*$S$9 -> 5000 | J37: 44.94 | K37: =J37/H37 -> 0.008988 | L37: 0.07 | N37: 0.17 | P37: 100 | Q37: 비비
B38: 치킨 염지제 | C38: Pickle Solution Powder Mix [G28484] | D38: HQ | E38: 5kg/4bag | F38: 20 | G38: kg | H38: =F38*$S$9 -> 20000 | I38: 1960.65 | J38: =+I38/$K$3 -> 74.422374 | K38: =J38/H38 -> 0.0037211187 | L38: 0.065 | M38: 0.003 | N38: 0.17 | P38: 98 | Q38: 일반(6.5%) / BB(0.3%) / 원료육 무게대비(17%)
B39: 저크 시즈닝 | C39: Jerk Seasoning | D39: HQ | E39: 5kg/4bag | F39: =5*4 -> 20 | G39: kg | H39: =F39*$S$9 -> 20000 | I39: 7587.37 | J39: =+I39/$K$3 -> 288.00147 | K39: =J39/H39 -> 0.014400074 | P39: 100
B40: 빠리배터믹스 [A82256] | C40: Battering Powder Mix (P-Type) [A82256] | E40: 5#/5bag | F40: 25 | G40: # | H40: =F40*S7 -> 11339.8 | J40: 72 | K40: =J40/H40 -> 0.0063493183 | L40: 0.1 | P40: 100 | Q40: 원료육 중량대비 10%
B41: 화이트 배터믹스 (White) | C41: Battering Powder Mix | D41: HQ | E41: 5kg/4bag | F41: 20 | G41: kg | H41: 20000 | I41: 2147.41 | J41: =+I41/$K$3 -> 81.511412 | K41: =J41/H41 -> 0.0040755706 | L41: 0.25 | P41: 85 | Q41: White Chicken: 원료육 중량대비 25%
B42: 비비윙스 파우더 [A20021] | C42: Batter Mix #8 [A20021] | E42: 50#/1bag | F42: 50 | G42: # | H42: =F42*S7 -> 22679.6 | J42: 77.68 | K42: =J42/H42 -> 0.0034251045 | P42: 100
B43: 옐로우 배터믹스 [Battering Powder Mix-C] | C43: Battering Powder Mix-C | D43: HQ | E43: 2kg/10bag | F43: 20 | G43: kg | H43: =F43*$S$9 -> 20000 | I43: 2349.93 | J43: =+I43/$K$3 -> 89.198668 | K43: =J43/H43 -> 0.0044599334 | L43: 0.11 | P43: 98 | Q43: 원료육 중량대비 10%
A45: 소스 | B45: 져크바베큐 소스 | C45: Jerk Barbecue Sauce (Cajun Sauce) | D45: HQ | E45: 2kg/5bag | F45: 10 | G45: kg | H45: =F45*S9 -> 10000 | I45: 1361.47 | J45: =+I45/$K$3 -> 51.678693 | K45: =J45/H45 -> 0.0051678693 | P45: 96
...

Sheet Prep
A1: 1. Sauce & Powder
A3: 김치 베이스 (Kimchi Base) | J3: 떡볶이 소스 믹스 (Ddeok-Bokki Sauce Mix) | S3: Jamaican Mayo
A4: Ingredients | D4: Weight (%) | E4: Input (g) | F4: Usage (%) | G4: Input+ Usage | H4: Price | J4: Ingredients | M4: Weight (%) | N4: Input (g) | O4: Usage (%) | P4: Input+ Usage | Q4: Price | S4: Ingredients | V4: Weight (%) | W4: Input (g) | X4: Usage (%) | Y4: Input+ Usage | Z4: Price
A6: 1 | B6: =Master!B80 -> 김치 | C6: =Master!C80 -> Kimchi (토바기) Korea | D6: 0.852 | E6: =D6*C14 -> 852 | F6: =Master!P80 -> 80 | G6: =E6/F6*100 -> 1065 | H6: =G6*Master!K80 -> 2.3171866 | J6: 1 | K6: =Master!B53 -> 떡볶이 소스 | L6: =Master!C53 -> Shin Alltokkbokki Sauce (New Hot Pepper) | M6: 0.25 | N6: =M6*L14 -> 2000 | O6: =Master!P53 -> 96 | P6: =N6/O6*100 -> 2083.3333 | Q6: =P6*Master!K53 -> 21.197651 | S6: 1 | T6: =Master!B68 -> 마요네즈 | U6: =Master!C68 -> Mayonnaise | V6: 0.5 | W6: 900 | X6: =Master!P68 -> 100 | Y6: =W6/X6*100 -> 900 | Z6: =Y6*Master!K68 -> 2.5941634
A7: 2 | B7: =Master!B74 -> 설탕 | C7: =Master!C74 -> White Sugar | D7: 0.028 | E7: =D7*C14 -> 28 | F7: =Master!P74 -> 100 | G7: =E7/F7*100 -> 28 | H7: =G7*Master!K74 -> 0.029289105 | S7: 2 | T7: =Master!B54 -> 마라핫 소스 | U7: =Master!C54 -> Mala Hot Sauce | V7: 0.5 | W7: 300 | X7: =Master!P54 -> 96 | Y7: =W7/X7*100 -> 312.5 | Z7: =Y7*Master!K54 -> 3.1611979
A8: 3 | B8: =Master!B64 -> 간장 | C8: =Master!C64 -> Soy Sauce (Maeil 12/1L) Korean | D8: 0.02 | E8: =D8*C14 -> 20 | F8: =Master!P64 -> 100 | G8: =E8/F8*100 -> 20 | H8: =G8*Master!K64 -> 0.065416667 | J8: 2 | K8: 물 | L8: Filtered Water | M8: 0.75 | N8: =M8*L14 -> 6000 | O8: 100 | P8: =N8/O8*100 -> 6000 | Q8: -
A9: 4 | B9: =Master!B63 -> 미원 | C9: =Master!C63 -> MSG (Ajinomodo) | D9: 0.012 | E9: =D9*C14 -> 12 | F9: =Master!P63 -> 100 | G9: =E9/F9*100 -> 12 | H9: =G9*Master!K63 -> 0.10295596
A10: 5 | B10: =Master!B58 -> 소고기 다시다 | C10: =Master!C58 -> DASHIDA SOGOGI(CJ) | D10: 0.034 | E10: =D10*C14 -> 34 | F10: =Master!P58 -> 100 | G10: =E10/F10*100 -> 34 | H10: =G10*Master!K58 -> 0.45569444
A11: 6 | B11: =Master!B78 -> 참기름 | C11: =Master!C78 -> Sesame Oil | D11: 0.014 | E11: =D11*C14 -> 14 | F11: =Master!P78 -> 100 | G11: =E11/F11*100 -> 14 | H11: =G11*Master!K78 -> 0.4388713
A12: 7 | B12: =Master!B59 -> 고추가루 | C12: =Master!C59 -> Red Chili Pepper | D12: 0.03 | E12: =D12*C14 -> 30 | F12: =Master!P59 -> 100 | G12: =E12/F12*100 -> 30 | H12: =G12*Master!K59 -> 0.23624755
A13: 8 | B13: =Master!B29 -> 카놀라유 | C13: =Master!C29 -> Canola Oil | D13: 0.01 | E13: =D13*C14 -> 10 | F13: =Master!P29 -> 100 | G13: =E13/F13*100 -> 10 | H13: =G13*Master!K29 -> 0.031185288 | S13: 600g | U13: 600 | V13: =SUM(V6:V12) -> 1 | W13: =SUM(W6:W12) -> 1200 | X13: - | Y13: - | Z13: =SUM(Z6:Z12) -> 5.7553613
A14: 1kg | C14: 1000 | D14: =SUM(D6:D13) -> 1 | E14: =SUM(E6:E13) -> 1000 | F14: - | G14: - | H14: =SUM(H6:H13) -> 3.676847 | J14: 8kg | L14: 8000 | M14: =SUM(M6:M13) -> 1 | N14: =SUM(N6:N13) -> 8000 | O14: - | P14: - | Q14: =SUM(Q6:Q13) -> 21.197651
A17: 스리라차 마요 (Sriracha Mayo) | J17: BB 파우더 (BB Powder) | S17: Soy Mayo
A18: Ingredients | D18: Weight (%) | E18: Input (g) | F18: Usage (%) | G18: Input+ Usage | H18: Price | J18: Ingredients | M18: Weight (%) | N18: Input (g) | O18: Usage (%) | P18: Input+ Usage | Q18: Price | S18: Ingredients | V18: Weight (%) | W18: Input (g) | X18: Usage (%) | Y18: Input+ Usage | Z18: Price
A20: 1 | B20: =Master!B68 -> 마요네즈 | C20: =Master!C68 -> Mayonnaise | D20: 0.058823 | E20: =D20*C25 -> 58.823 | F20: =Master!P68 -> 100 | G20: =E20/F20*100 -> 58.823 | H20: =G20*Master!K68 -> 0.16955164 | J20: 1 | K20: =Master!B42 -> 비비윙스 파우더 [A20021] | L20: =Master!C42 -> Batter Mix #8 [A20021] | M20: 0.3 | N20: =M20*L25 -> 3000 | O20: =Master!P42 -> 100 | P20: =N20/O20*100 -> 3000 | Q20: =P20*Master!K42 -> 10.275313 | S20: 1 | T20: =Master!B48 -> 소이갈릭소스 | U20: =Master!C48 -> Garlic Flavor Soy Sauce | V20: 0.5 | W20: 300 | X20: =Master!P48 -> 96 | Y20: =W20/X20*100 -> 312.5 | Z20: =Y20*Master!K48 -> 2.1784102
A21: 2 | B21: =Master!B66 -> 스리라차 소스 | C21: =Master!C66 -> Sriracha Sauce | D21: 0.941176 | E21: =D21*C25 -> 941.176 | F21: =Master!P66 -> 100 | G21: =E21/F21*100 -> 941.176 | H21: =G21*Master!K66 -> 7.2415392 | J21: 2 | K21: =Master!B41 -> 화이트 배터믹스 (White) | L21: =Master!C41 -> Battering Powder Mix | M21: 0.7 | N21: =M21*L25 -> 7000 | O21: =Master!P41 -> 85 | P21: =N21/O21*100 -> 8235.2941 | Q21: =P21*Master!K41 -> 33.563523 | S21: 2 | T21: =Master!B68 -> 마요네즈 | U21: =Master!C68 -> Mayonnaise | V21: 0.5 | W21: 900 | X21: =Master!P68 -> 100 | Y21: =W21/X21*100 -> 900 | Z21: =Y21*Master!K68 -> 2.5941634
A25: 1kg | C25: 1000 | D25: =SUM(D20:D24) -> 0.999999 | E25: =SUM(E20:E24) -> 999.999 | F25: - | G25: - | H25: =SUM(H20:H24) -> 7.4110908 | J25: 10kg | L25: 10000 | M25: =SUM(M20:M24) -> 1 | N25: =SUM(N20:N24) -> 10000 | O25: - | P25: - | Q25: =SUM(Q20:Q24) -> 43.838836
S27: 600g | U27: 600 | V27: =SUM(V20:V26) -> 1 | W27: =SUM(W20:W26) -> 1200 | X27: - | Y27: - | Z27: =SUM(Z20:Z26) -> 4.7725736
A28: 2. Sides
A30: 콜슬로우 (Coleslaw) | J30: 콘샐러드 (Corn Salad) | S30: Mala Mayo
A31: Ingredients | D31: Weight (%) | E31: Input (g) | F31: Usage (%) | G31: Input+ Usage | H31: Price | J31: Ingredients | M31: Weight (%) | N31: Input (g) | O31: Usage (%) | P31: Input+ Usage | Q31: Price | S31: Ingredients | V31: Weight (%) | W31: Input (g) | X31: Usage (%) | Y31: Input+ Usage | Z31: Price
A33: 1 | B33: =Master!B107 -> 양배추 | C33: =Master!C107 -> Cabbage | D33: 0.63 | E33: =D33*C46 -> 3150 | F33: =Master!P107 -> 79 | G33: =E33/F33*100 -> 3987.3418 | H33: =G33*Master!K107 -> 3.3367335 | J33: 1 | K33: =Master!B109 -> 옥수수(스위트콘) | L33: =Master!C109 -> Sweet Corn | M33: 0.675 | N33: =M33*L46 -> 3375 | O33: =Master!P109 -> 50 | P33: =N33/O33*100 -> 6750 | Q33: =P33*Master!K109 -> 25.418759 | S33: 1 | T33: =Master!B54 -> 마라핫 소스 | U33: =Master!C54 -> Mala Hot Sauce | V33: 0.5 | W33: 300 | X33: =Master!P54 -> 96 | Y33: =W33/X33*100 -> 312.5 | Z33: =Y33*Master!K54 -> 3.1611979
A34: 2 | B34: =Master!B108 -> 당근 | C34: =Master!C108 -> Carrot | D34: 0.037 | E34: =D34*C46 -> 185 | F34: =Master!P108 -> 81.3 | G34: =E34/F34*100 -> 227.55228 | H34: =G34*Master!K108 -> 0.20946522 | J34: 2 | K34: =Master!B68 -> 마요네즈 | L34: =Master!C68 -> Mayonnaise | M34: 0.14 | N34: =M34*L46 -> 700 | O34: =Master!P68 -> 100 | P34: =N34/O34*100 -> 700 | Q34: =P34*Master!K68 -> 2.0176826 | S34: 2 | T34: =Master!B68 -> 마요네즈 | U34: =Master!C68 -> Mayonnaise | V34: 0.5 | W34: 900 | X34: =Master!P68 -> 100 | Y34: =W34/X34*100 -> 900 | Z34: =Y34*Master!K68 -> 2.5941634
A35: 3 | B35: =Master!B104 -> 양파 | C35: =Master!C104 -> Onion | D35: 0.027 | E35: =D35*C46 -> 135 | F35: =Master!P104 -> 89 | G35: =E35/F35*100 -> 151.68539 | H35: =G35*Master!K104 -> 0.2030962 | J35: 3 | K35: =Master!B74 -> 설탕 | L35: =Master!C74 -> White Sugar | M35: 0.03 | N35: =M35*L46 -> 150 | O35: =Master!P74 -> 100 | P35: =N35/O35*100 -> 150 | Q35: =P35*Master!K74 -> 0.15690592
A36: 4 | B36: =Master!B68 -> 마요네즈 | C36: =Master!C68 -> Mayonnaise | D36: 0.12 | E36: =D36*C46 -> 600 | F36: =Master!P68 -> 100 | G36: =E36/F36*100 -> 600 | H36: =G36*Master!K68 -> 1.7294423 | J36: 4 | K36: =Master!B75 -> 소금 | L36: =Master!C75 -> Salt | M36: 0.002 | N36: =M36*L46 -> 10 | O36: =Master!P75 -> 100 | P36: =N36/O36*100 -> 10 | Q36: =P36*Master!K75 -> 0.0044184707
A37: 5 | B37: =Master!B67 -> 물엿 | C37: =Master!C67 -> Corn Syrup | D37: 0.07 | E37: =D37*C46 -> 350 | F37: =Master!P67 -> 100 | G37: =E37/F37*100 -> 350 | H37: =G37*Master!K67 -> 2.0868487 | J37: 5 | K37: =Master!B108 -> 당근 | L37: =Master!C108 -> Carrot | M37: 0.028 | N37: =M37*L46 -> 140 | O37: =Master!P108 -> 81.3 | P37: =N37/O37*100 -> 172.20172 | Q37: =P37*Master!K108 -> 0.15851422
A38: 6 | B38: =Master!B74 -> 설탕 | C38: =Master!C74 -> White Sugar | D38: 0.068 | E38: =D38*C46 -> 340 | F38: =Master!P74 -> 100 | G38: =E38/F38*100 -> 340 | H38: =G38*Master!K74 -> 0.35565342 | J38: 6 | K38: =Master!B104 -> 양파 | L38: =Master!C104 -> Onion | M38: 0.019 | N38: =M38*L46 -> 95 | O38: =Master!P104 -> 89 | P38: =N38/O38*100 -> 106.74157 | Q38: =P38*Master!K104 -> 0.14291955
A39: 7 | B39: =Master!B69 -> 식초 | C39: =Master!C69 -> Vinegar Distilled | D39: 0.022 | E39: =D39*C46 -> 110 | F39: =Master!P69 -> 100 | G39: =E39/F39*100 -> 110 | H39: =G39*Master!K69 -> 0.11581675 | J39: 7 | K39: =Master!B110 -> 홍피망 | L39: =Master!C110 -> Red Bell Pepper | M39: 0.021 | N39: =M39*L46 -> 105 | O39: =Master!P110 -> 65 | P39: =N39/O39*100 -> 161.53846 | Q39: =P39*Master!K110 -> 1.1396212
A40: 8 | B40: =Master!B73 -> 레몬주스 | C40: =Master!C73 -> Lemon Juice | D40: 0.02 | E40: =D40*C46 -> 100 | F40: =Master!P73 -> 100 | G40: =E40/F40*100 -> 100 | H40: =G40*Master!K73 -> 0.30082272 | J40: 8 | K40: =Master!B111 -> 청피망 | L40: =Master!C111 -> Green Bell Pepper | M40: 0.021 | N40: =M40*L46 -> 105 | O40: =Master!P111 -> 65 | P40: =N40/O40*100 -> 161.53846 | Q40: =P40*Master!K111 -> 0.54072194 | S40: 600g | U40: 600 | V40: =SUM(V33:V39) -> 1 | W40: =SUM(W33:W39) -> 1200 | X40: - | Y40: - | Z40: =SUM(Z33:Z39) -> 5.7553613
A41: 9 | B41: =Master!B75 -> 소금 | C41: =Master!C75 -> Salt | D41: 0.006 | E41: =D41*C46 -> 30 | F41: =Master!P75 -> 100 | G41: =E41/F41*100 -> 30 | H41: =G41*Master!K75 -> 0.013255412 | J41: 9 | K41: =Master!B32 -> 올리브오일 | L41: =Master!C32 -> Oilve Oil | M41: 0.02 | N41: =M41*L46 -> 100 | O41: =Master!P32 -> 100 | P41: =N41/O41*100 -> 100 | Q41: =P41*Master!K32 -> 1.4939893
J42: 10 | K42: =Master!B67 -> 물엿 | L42: =Master!C67 -> Corn Syrup | M42: 0.015 | N42: =M42*L46 -> 75 | O42: =Master!P67 -> 100 | P42: =N42/O42*100 -> 75 | Q42: =P42*Master!K67 -> 0.44718187 | S42: Spicy Mayo
J43: 11 | K43: =Master!B69 -> 식초 | L43: =Master!C69 -> Vinegar Distilled | M43: 0.015 | N43: =M43*L46 -> 75 | O43: =Master!P69 -> 100 | P43: =N43/O43*100 -> 75 | Q43: =P43*Master!K69 -> 0.078965963 | S43: Ingredients | V43: Weight (%) | W43: Input (g) | X43: Usage (%) | Y43: Input+ Usage | Z43: Price
J44: 12 | K44: =Master!B73 -> 레몬주스 | L44: =Master!C73 -> Lemon Juice | M44: 0.004 | N44: =M44*L46 -> 20 | O44: =Master!P73 -> 100 | P44: =N44/O44*100 -> 20 | Q44: =P44*Master!K73 -> 0.060164543
J45: 13 | K45: =Master!B71 -> 미림 | L45: =Master!C71 -> Rice Wine(Cook wine) | M45: 0.01 | N45: =M45*L46 -> 50 | O45: =Master!P71 -> 100 | P45: =N45/O45*100 -> 50 | Q45: =P45*Master!K71 -> 0.58834917 | S45: 1 | T45: =Master!B50 -> 매운양념 소스 | U45: =Master!C50 -> Hot Spicy Sauce | V45: 0.5 | W45: 300 | X45: =Master!P50 -> 96 | Y45: =W45/X45*100 -> 312.5 | Z45: =Y45*Master!K50 -> 1.744135
A46: 5kg | C46: 5000 | D46: =SUM(D33:D45) -> 1 | E46: =SUM(E33:E45) -> 5000 | F46: - | G46: - | H46: =SUM(H33:H45) -> 8.3511342 | J46: 5kg | L46: 5000 | M46: =SUM(M33:M45) -> 1 | N46: =SUM(N33:N45) -> 5000 | O46: - | P46: - | Q46: =SUM(Q33:Q45) -> 32.248194 | S46: 2 | T46: =Master!B68 -> 마요네즈 | U46: =Master!C68 -> Mayonnaise | V46: 0.5 | W46: 900 | X46: =Master!P68 -> 100 | Y46: =W46/X46*100 -> 900 | Z46: =Y46*Master!K68 -> 2.5941634
A49: 치킨무 (Pickled Radish) | J49: 밥 (Steamed Rice)
A50: Ingredients | D50: Weight (%) | E50: Input (g) | F50: Usage (%) | G50: Input+ Usage | H50: Price | J50: Ingredients | M50: Weight (%) | N50: Input (g) | O50: Usage (%) | P50: Input+ Usage | Q50: Price
A52: 1 | B52: =Master!B219 -> 흰 무 | C52: =Master!C219 -> White Radish | D52: 0.5707 | E52: =D52*C59 -> 19061.38 | F52: =Master!P219 -> 90 | G52: =E52/F52*100 -> 21179.311 | H52: =G52*Master!K219 -> 21.478516 | J52: 1 | K52: =Master!B84 -> 쌀 | L52: =Master!C84 -> Grain Rice (Rice Golden) | M52: 0.5 | N52: =M52*L59 -> 1500 | O52: =Master!P84 -> 100 | P52: =N52/O52*100 -> 1500 | Q52: =P52*Master!K84 -> 1.907976 | S52: 600g | U52: 600 | V52: =SUM(V45:V51) -> 1 | W52: =SUM(W45:W51) -> 1200 | X52: - | Y52: - | Z52: =SUM(Z45:Z51) -> 4.3382984
A53: 2 | B53: =Master!B75 -> 소금 | C53: =Master!C75 -> Salt | D53: 0.0046 | E53: =D53*C59 -> 153.64 | F53: =Master!P75 -> 100 | G53: =E53/F53*100 -> 153.64 | H53: =G53*Master!K75 -> 0.067885384 | J53: 2 | K53: 물 | L53: Filtered Water | M53: 0.5 | N53: =M53*L60 -> 0 | O53: 100 | P53: =N53/O53*100 -> 0 | Q53: -
A54: 3 | B54: =Master!B104 -> 양파 | C54: =Master!C104 -> Onion | D54: 0.0092 | E54: =D54*C59 -> 307.28 | F54: =Master!P104 -> 89 | G54: =E54/F54*100 -> 345.25843 | H54: =G54*Master!K104 -> 0.46227705 | S54: Creamy Onions Sauce ※Shelft life : 3 Days
...

Sheet BI_Golden Fried(5pc)
A1: RECIPE COST CALCULATOR
B3: ITEM NAME | D3: Golden Fried_Bone In_5pcs_0.5Bird
B5: EST. SALE PPRICE | D5: ='Honduras(Total Final)'!G6 -> 12.170385
B6: TOTAL COST(Dine In) | D6: =$J$25 -> 4.5800398
B7: TOTAL COStT(Take Out) | D7: =$J$40 -> 5.3742867
B9: Food Cost | D9: =IF(D7="","",IF(ISBLANK(D5),"",D7/D5)) -> 0.44158722
B11: NET PROFIT | D11: =D5-D7 -> 6.7960987
B13: PRIMARY INGREDIENTS
B14: Product Name | D14: Weight (g) | E14: Price | F14: Price/g | G14: Input/g | H14: Usage(%) | I14: Input+ Usage | J14: Price | K14: Price(%)/ Portion
B16: =Master!$B$6 -> 홀치킨 | C16: =Master!$C$6 -> Whole Chicken | D16: =Master!$H$6 -> 1000 | E16: =Master!$J$6 -> 2.8453325 | F16: =Master!$K$6 -> 0.0028453325 | G16: 650 | H16: =Master!$P$6 -> 98 | I16: =G16/H16*100 -> 663.26531 | J16: =F16*I16 -> 1.8872103 | K16: =J16/$J$40% -> 35.11555
B17: =Master!$B$36 -> #2 마리네이드 파우더 | C17: =Master!$C$36 -> Marinade Powder Mix | D17: =Master!$H$36 -> 20000 | E17: =Master!$J$36 -> 158.02869 | F17: =Master!$K$36 -> 0.0079014344 | G17: =G16*0.013 -> 8.45 | H17: =Master!$P$36 -> 98 | I17: =G17/H17*100 -> 8.622449 | J17: =F17*I17 -> 0.068129715 | K17: =J17/$J$40% -> 1.2676978
B18: =Master!$B$41 -> 화이트 배터믹스 (White) | C18: =Master!$C$41 -> Battering Powder Mix | D18: =Master!$H$41 -> 20000 | E18: =Master!$J$41 -> 81.511412 | F18: =Master!$K$41 -> 0.0040755706 | G18: =G16*25% -> 162.5 | H18: =Master!$P$41 -> 85 | I18: =G18/H18*100 -> 191.17647 | J18: =F18*I18 -> 0.7791532 | K18: =J18/$J$40% -> 14.497798
B19: =Master!$B$31 -> 해바라기 유 | C19: =Master!$C$31 -> Sunflower Oil | D19: =Master!$H$31 -> 1320 | E19: =Master!$J$31 -> 14.991516 | F19: =Master!$K$31 -> 0.011357209 | G19: =G16*25% -> 162.5 | H19: =Master!$P$31 -> 100 | I19: =G19/H19*100 -> 162.5 | J19: =F19*I19 -> 1.8455465 | K19: =J19/$J$40% -> 34.340306
B25: TOTAL | G25: =SUM(G16:G24) -> 983.45 | J25: =SUM(J16:J24) -> 4.5800398 | K25: =SUM(K16:K24) -> 85.221352
B27: SECONDARY INGREDIENTS
B28: Product Name | D28: Weight (g) | E28: Price | F28: Price/g | G28: Input/g | H28: Usage(%) | I28: Input+ Usage | J28: Price | K28: Price(%)/ Portion
B30: =Master!$B$150 -> 치킨패키지(대) | C30: =Master!$C$150 -> Chicken Package (L) | D30: =Master!$H$150 -> 400 | E30: =Master!$J$150 -> 99.157712 | F30: =Master!$K$150 -> 0.24789428 | G30: 1 | H30: =Master!$P$150 -> 100 | I30: =G30/H30*100 -> 1 | J30: =F30*I30 -> 0.24789428 | K30: =J30/$J$40% -> 4.6125987
B31: =Master!$B$157 -> 치킨트레이(소) | C31: =Master!$C$157 -> To Go Tray (S) | D31: =Master!$H$157 -> 100 | E31: =Master!$J$157 -> 8.4 | F31: =Master!$K$157 -> 0.084 | G31: 0 | H31: =Master!$P$157 -> 100 | I31: =G31/H31*100 -> 0 | J31: =F31*I31 -> 0 | K31: =J31/$J$40% -> 0
B32: =Master!$B$175 -> 종이백 (S,M) | C32: =Master!$C$175 -> Paper Bag (S,M) | D32: =Master!$H$175 -> 200 | E32: =Master!$J$175 -> 61.188313 | F32: =Master!$K$175 -> 0.30594157 | G32: 1 | H32: =Master!$P$175 -> 100 | I32: =G32/H32*100 -> 1 | J32: =F32*I32 -> 0.30594157 | K32: =J32/$J$40% -> 5.6926916
B33: =Master!$B$166 -> 비비큐 냅킨 | C33: =Master!$C$166 -> BBQ New LOGO Napkin | D33: =Master!$H$166 -> 5000 | E33: =Master!$J$166 -> 21.845974 | F33: =Master!$K$166 -> 0.0043691948 | G33: 1 | H33: =Master!$P$166 -> 100 | I33: =G33/H33*100 -> 1 | J33: =F33*I33 -> 0.0043691948 | K33: =J33/$J$40% -> 0.081298134
B34: =Master!$B$164 -> 비비큐 젓가락 | C34: =Master!$C$164 -> BBQ Chopstick Logo | D34: =Master!$H$164 -> 500 | E34: =Master!$J$164 -> 118.02095 | F34: =Master!$K$164 -> 0.23604189 | G34: 1 | H34: =Master!$P$164 -> 100 | I34: =G34/H34*100 -> 1 | J34: =F34*I34 -> 0.23604189 | K34: =J34/$J$40% -> 4.3920599
B35: =Master!$B$165 -> 왁스페이퍼 | C35: =Master!$C$165 -> BBQ Wax Paper Logo / Parchment paper | D35: =Master!$H$165 -> 2500 | E35: =Master!$J$165 -> 36.619611 | F35: =Master!$K$165 -> 0.014647845 | G35: 0 | H35: =Master!$P$165 -> 100 | I35: =G35/H35*100 -> 0 | J35: =F35*I35 -> 0 | K35: =J35/$J$40% -> 0
B38: TOTAL | G38: =SUM(G30:G37) -> 4 | J38: =SUM(J30:J37) -> 0.79424693 | K38: =SUM(K30:K37) -> 14.778648
B40: TOTAL INGREDIENTS | J40: =J25+J38 -> 5.3742867 | K40: =K25+K38 -> 100

Sheet BI_Golden Fried(10pc)
A1: RECIPE COST CALCULATOR
B3: ITEM NAME | D3: Golden Fried_Bone In_10pcs_1 Bird
B5: EST. SALE PPRICE | D5: ='Honduras(Total Final)'!G7 -> 24.340771
B6: TOTAL COST(Dine In) | D6: =J25 -> 9.1600795
B7: TOTAL COStT(Take Out) | D7: =J40 -> 10.043421
B9: Food Cost | D9: =IF(D7="","",IF(ISBLANK(D5),"",D7/D5)) -> 0.41261721
B11: NET PROFIT | D11: =D5-D7 -> 14.29735
B13: PRIMARY INGREDIENTS
B14: Product Name | D14: Weight (g) | E14: Price | F14: Price/g | G14: Input/g | H14: Usage(%) | I14: Input+ Usage | J14: Price | K14: Price(%)/ Portion
B16: =Master!$B$6 -> 홀치킨 | C16: =Master!$C$6 -> Whole Chicken | D16: =Master!$H$6 -> 1000 | E16: =Master!$J$6 -> 2.8453325 | F16: =Master!$K$6 -> 0.0028453325 | G16: 1300 | H16: =Master!$P$6 -> 98 | I16: =G16/H16*100 -> 1326.5306 | J16: =F16*I16 -> 3.7744207 | K16: =J16/$J$40% -> 37.581026
B17: =Master!$B$36 -> #2 마리네이드 파우더 | C17: =Master!$C$36 -> Marinade Powder Mix | D17: =Master!$H$36 -> 20000 | E17: =Master!$J$36 -> 158.02869 | F17: =Master!$K$36 -> 0.0079014344 | G17: =G16*0.013 -> 16.9 | H17: =Master!$P$36 -> 98 | I17: =G17/H17*100 -> 17.244898 | J17: =F17*I17 -> 0.13625943 | K17: =J17/$J$40% -> 1.3567034
B18: =Master!$B$41 -> 화이트 배터믹스 (White) | C18: =Master!$C$41 -> Battering Powder Mix | D18: =Master!$H$41 -> 20000 | E18: =Master!$J$41 -> 81.511412 | F18: =Master!$K$41 -> 0.0040755706 | G18: =G16*25% -> 325 | H18: =Master!$P$41 -> 85 | I18: =G18/H18*100 -> 382.35294 | J18: =F18*I18 -> 1.5583064 | K18: =J18/$J$40% -> 15.515694
B19: =Master!$B$31 -> 해바라기 유 | C19: =Master!$C$31 -> Sunflower Oil | D19: =Master!$H$31 -> 1320 | E19: =Master!$J$31 -> 14.991516 | F19: =Master!$K$31 -> 0.011357209 | G19: =G16*25% -> 325 | H19: =Master!$P$31 -> 100 | I19: =G19/H19*100 -> 325 | J19: =F19*I19 -> 3.691093 | K19: =J19/$J$40% -> 36.751353
B25: TOTAL | G25: =SUM(G16:G24) -> 1966.9 | J25: =SUM(J16:J24) -> 9.1600795 | K25: =SUM(K16:K24) -> 91.204776
B27: SECONDARY INGREDIENTS
B28: Product Name | D28: Weight (g) | E28: Price | F28: Price/g | G28: Input/g | H28: Usage(%) | I28: Input+ Usage | J28: Price | K28: Price(%)/ Portion
B30: =Master!$B$153 -> 치킨버켓 | C30: =Master!$C$153 -> Chicken Bucket | D30: =Master!$H$153 -> 300 | E30: =Master!$J$153 -> 92.78608 | F30: =Master!$K$153 -> 0.30928693 | G30: 1 | H30: =Master!$P$153 -> 100 | I30: =G30/H30*100 -> 1 | J30: =F30*I30 -> 0.30928693 | K30: =J30/$J$40% -> 3.0794979
B31: =Master!$B$156 -> 치킨트레이(중) | C31: =Master!$C$156 -> To Go Tray (M) | D31: =Master!$H$156 -> 100 | E31: =Master!$J$156 -> 9.24 | F31: =Master!$K$156 -> 0.0924 | G31: 0 | H31: =Master!$P$156 -> 100 | I31: =G31/H31*100 -> 0 | J31: =F31*I31 -> 0 | K31: =J31/$J$40% -> 0
B32: =Master!$B$174 -> 종이백 (L) | C32: =Master!$C$174 -> Paper Bag (L) | D32: =Master!$H$174 -> 200 | E32: =Master!$J$174 -> 66.728665 | F32: =Master!$K$174 -> 0.33364332 | G32: 1 | H32: =Master!$P$174 -> 100 | I32: =G32/H32*100 -> 1 | J32: =F32*I32 -> 0.33364332 | K32: =J32/$J$40% -> 3.3220088
B33: =Master!$B$166 -> 비비큐 냅킨 | C33: =Master!$C$166 -> BBQ New LOGO Napkin | D33: =Master!$H$166 -> 5000 | E33: =Master!$J$166 -> 21.845974 | F33: =Master!$K$166 -> 0.0043691948 | G33: 1 | H33: =Master!$P$166 -> 100 | I33: =G33/H33*100 -> 1 | J33: =F33*I33 -> 0.0043691948 | K33: =J33/$J$40% -> 0.043503054
B34: =Master!$B$164 -> 비비큐 젓가락 | C34: =Master!$C$164 -> BBQ Chopstick Logo | D34: =Master!$H$164 -> 500 | E34: =Master!$J$164 -> 118.02095 | F34: =Master!$K$164 -> 0.23604189 | G34: 1 | H34: =Master!$P$164 -> 100 | I34: =G34/H34*100 -> 1 | J34: =F34*I34 -> 0.23604189 | K34: =J34/$J$40% -> 2.3502141
B35: =Master!$B$165 -> 왁스페이퍼 | C35: =Master!$C$165 -> BBQ Wax Paper Logo / Parchment paper | D35: =Master!$H$165 -> 2500 | E35: =Master!$J$165 -> 36.619611 | F35: =Master!$K$165 -> 0.014647845 | G35: 0 | H35: =Master!$P$165 -> 100 | I35: =G35/H35*100 -> 0 | J35: =F35*I35 -> 0 | K35: =J35/$J$40% -> 0
B38: TOTAL | G38: =SUM(G30:G37) -> 4 | J38: =SUM(J30:J37) -> 0.88334134 | K38: =SUM(K30:K37) -> 8.7952238
B40: TOTAL INGREDIENTS | J40: =J25+J38 -> 10.043421 | K40: =K25+K38 -> 100

Sheet BI_Classic(5pc)
A1: RECIPE COST CALCULATOR
B3: ITEM NAME | D3: Classic_Bone In_5pcs_0.5Bird
B5: EST. SALE PPRICE | D5: ='Honduras(Total Final)'!G8 -> 12.170385
B6: TOTAL COST(Dine In) | D6: =J26 -> 4.0285688
B7: TOTAL COStT(Take Out) | D7: =J42 -> 4.7018843
B9: Food Cost | D9: =IF(D7="","",IF(ISBLANK(D5),"",D7/D5)) -> 0.38633816
B11: NET PROFIT | D11: =D5-D7 -> 7.4685011
B13: PRIMARY INGREDIENTS
B14: Product Name | D14: Wheigh (g) | E14: Price | F14: Price/g | G14: Input/g | H14: Usage(%) | I14: Input+ Usage | J14: Price | K14: Price(%)/ Portion
B16: =Master!$B$6 -> 홀치킨 | C16: =Master!$C$6 -> Whole Chicken | D16: =Master!$H$6 -> 1000 | E16: =Master!$J$6 -> 2.8453325 | F16: =Master!$K$6 -> 0.0028453325 | G16: 650 | H16: =Master!$P$6 -> 98 | I16: =G16/H16*100 -> 663.26531 | J16: =F16*I16 -> 1.8872103 | K16: =J16/$J$42% -> 40.137319
B17: =Master!$B$43 -> 옐로우 배터믹스 [Battering Powder Mix-C] | C17: =Master!$C$43 -> Battering Powder Mix-C | D17: =Master!$H$43 -> 20000 | E17: =Master!$J$43 -> 89.198668 | F17: =Master!$K$43 -> 0.0044599334 | G17: =G16*10% -> 65 | H17: =Master!$P$43 -> 98 | I17: =G17/H17*100 -> 66.326531 | J17: =F17*I17 -> 0.29581191 | K17: =J17/$J$42% -> 6.2913481
B18: =Master!$B$31 -> 해바라기 유 | C18: =Master!$C$31 -> Sunflower Oil | D18: =Master!$H$31 -> 1320 | E18: =Master!$J$31 -> 14.991516 | F18: =Master!$K$31 -> 0.011357209 | G18: =G16*25% -> 162.5 | H18: =Master!$P$31 -> 100 | I18: =G18/H18*100 -> 162.5 | J18: =F18*I18 -> 1.8455465 | K18: =J18/$J$42% -> 39.251211
B26: TOTAL | G26: =SUM(G16:G25) -> 877.5 | J26: =SUM(J16:J25) -> 4.0285688 | K26: =SUM(K16:K25) -> 85.679878
B28: SECONDARY INGREDIENTS
B29: Product Name | D29: Wheigh (g) | E29: Price | F29: Price/g | G29: Input/g | H29: Usage(%) | I29: Input+ Usage | J29: Price | K29: Price(%)/ Portion
B31: =Master!$B$151 -> 치킨패키지(중) | C31: =Master!$C$151 -> Chicken Package (M) | D31: =Master!$H$151 -> 400 | E31: =Master!$J$151 -> 50.785161 | F31: =Master!$K$151 -> 0.1269629 | G31: 1 | H31: =Master!$P$151 -> 100 | I31: =G31/H31*100 -> 1 | J31: =F31*I31 -> 0.1269629 | K31: =J31/$J$42% -> 2.7002558
B32: =Master!$B$157 -> 치킨트레이(소) | C32: =Master!$C$157 -> To Go Tray (S) | D32: =Master!$H$157 -> 100 | E32: =Master!$J$157 -> 8.4 | F32: =Master!$K$157 -> 0.084 | G32: 0 | H32: =Master!$P$157 -> 100 | I32: =G32/H32*100 -> 0 | J32: =F32*I32 -> 0 | K32: =J32/$J$42% -> 0
B33: =Master!$B$175 -> 종이백 (S,M) | C33: =Master!$C$175 -> Paper Bag (S,M) | D33: =Master!$H$175 -> 200 | E33: =Master!$J$175 -> 61.188313 | F33: =Master!$K$175 -> 0.30594157 | G33: 1 | H33: =Master!$P$175 -> 100 | I33: =G33/H33*100 -> 1 | J33: =F33*I33 -> 0.30594157 | K33: =J33/$J$42% -> 6.5067864
B34: =Master!$B$166 -> 비비큐 냅킨 | C34: =Master!$C$166 -> BBQ New LOGO Napkin | D34: =Master!$H$166 -> 5000 | E34: =Master!$J$166 -> 21.845974 | F34: =Master!$K$166 -> 0.0043691948 | G34: 1 | H34: =Master!$P$166 -> 100 | I34: =G34/H34*100 -> 1 | J34: =F34*I34 -> 0.0043691948 | K34: =J34/$J$42% -> 0.092924336
B35: =Master!$B$165 -> 왁스페이퍼 | C35: =Master!$C$165 -> BBQ Wax Paper Logo / Parchment paper | D35: =Master!$H$165 -> 2500 | E35: =Master!$J$165 -> 36.619611 | F35: =Master!$K$165 -> 0.014647845 | G35: 0 | H35: =Master!$P$165 -> 100 | I35: =G35/H35*100 -> 0 | J35: =F35*I35 -> 0 | K35: =J35/$J$42% -> 0
B36: =Master!$B$164 -> 비비큐 젓가락 | C36: =Master!$C$164 -> BBQ Chopstick Logo | D36: =Master!$H$164 -> 500 | E36: =Master!$J$164 -> 118.02095 | F36: =Master!$K$164 -> 0.23604189 | G36: 1 | H36: =Master!$P$164 -> 100 | I36: =G36/H36*100 -> 1 | J36: =F36*I36 -> 0.23604189 | K36: =J36/$J$42% -> 5.0201552
B40: TOTAL | G40: =SUM(G31:G39) -> 4 | J40: =SUM(J31:J39) -> 0.67331556 | K40: =SUM(K31:K39) -> 14.320122
B42: TOTAL INGREDIENTS | J42: =J26+J40 -> 4.7018843 | K42: =K26+K40 -> 100

Sheet BI_Classic(10pc)
A1: RECIPE COST CALCULATOR
B3: ITEM NAME | D3: Classic_Bone In_10 pcs_1 Bird
B5: EST. SALE PPRICE | D5: ='Honduras(Total Final)'!G9 -> 24.340771
B6: TOTAL COST(Dine In) | D6: =$J$26 -> 8.0571375
B7: TOTAL COStT(Take Out) | D7: =$J$42 -> 8.9404789
B9: Food Cost | D9: =IF(D7="","",IF(ISBLANK(D5),"",D7/D5)) -> 0.36730467
B11: NET PROFIT | D11: =D5-D7 -> 15.400292
B13: PRIMARY INGREDIENTS
B14: Product Name | D14: Wheigh (g) | E14: Price | F14: Price/g | G14: Input/g | H14: Usage(%) | I14: Input+ Usage | J14: Price | K14: Price(%)/ Portion
B16: =Master!$B$6 -> 홀치킨 | C16: =Master!$C$6 -> Whole Chicken | D16: =Master!$H$6 -> 1000 | E16: =Master!$J$6 -> 2.8453325 | F16: =Master!$K$6 -> 0.0028453325 | G16: 1300 | H16: =Master!$P$6 -> 98 | I16: =G16/H16*100 -> 1326.5306 | J16: =F16*I16 -> 3.7744207 | K16: =J16/$J$42% -> 42.217209
B17: =Master!$B$43 -> 옐로우 배터믹스 [Battering Powder Mix-C] | C17: =Master!$C$43 -> Battering Powder Mix-C | D17: =Master!$H$43 -> 20000 | E17: =Master!$J$43 -> 89.198668 | F17: =Master!$K$43 -> 0.0044599334 | G17: =G16*10% -> 130 | H17: =Master!$P$43 -> 98 | I17: =G17/H17*100 -> 132.65306 | J17: =F17*I17 -> 0.59162382 | K17: =J17/$J$42% -> 6.6173617
B18: =Master!$B$31 -> 해바라기 유 | C18: =Master!$C$31 -> Sunflower Oil | D18: =Master!$H$31 -> 1320 | E18: =Master!$J$31 -> 14.991516 | F18: =Master!$K$31 -> 0.011357209 | G18: =G16*25% -> 325 | H18: =Master!$P$31 -> 100 | I18: =G18/H18*100 -> 325 | J18: =F18*I18 -> 3.691093 | K18: =J18/$J$42% -> 41.285183
B26: TOTAL | G26: =SUM(G16:G25) -> 1755 | J26: =SUM(J16:J25) -> 8.0571375 | K26: =SUM(K16:K25) -> 90.119754
B28: SECONDARY INGREDIENTS
B29: Product Name | D29: Wheigh (g) | E29: Price | F29: Price/g | G29: Input/g | H29: Usage(%) | I29: Input+ Usage | J29: Price | K29: Price(%)/ Portion
